<?xml version="1.0" ?>
<!-- =================================================================================== -->
<!-- |    This document was autogenerated by xacro from cuarm.xacro                    | -->
<!-- |    EDITING THIS FILE BY HAND IS NOT RECOMMENDED                                 | -->
<!-- =================================================================================== -->
<robot name="cuarm" xmlns:xacro="http://www.ros.org/wiki/xacro">
  <!-- math constants -->
  <!-- staubli geometry files are in millimeters -->
  <!-- named paths -->
  <!-- link macro -->
  <!-- Colors -->
  <!-- useful macros -->
  <link name="base_link">
    <visual>
      <geometry>
        <cylinder length="0.0" radius="0.02"/>
      </geometry>
      <material name="gray">
        <color rgba="0.5 0.5 0.5 1.0"/>
      </material>
      <origin rpy="0 0 0" xyz="0 0 0.0"/>
    </visual>
    <collision>
      <geometry>
        <cylinder length="0.0" radius="0.02"/>
      </geometry>
    </collision>
  </link>
  <link name="base_box">
    <visual>
      <geometry>
        <box size="0.09 0.14 0.14"/>
      </geometry>
      <material name="yellow">
        <color rgba="0.75 0.75 0 1.0"/>
      </material>
    </visual>
    <collision>
      <geometry>
        <box size="0.09 0.14 0.14"/>
      </geometry>
    </collision>
  </link>
  <link name="first_link">
    <visual>
      <geometry>
        <box size="0.09 0.14 0.15"/>
      </geometry>
      <material name="yellow">
        <color rgba="0.75 0.75 0 1.0"/>
      </material>
    </visual>
    <collision>
      <geometry>
        <box size="0.09 0.14 0.15"/>
      </geometry>
    </collision>
  </link>
  <link name="second_link">
    <visual>
      <geometry>
        <cylinder length="0.0" radius="0.02"/>
      </geometry>
      <material name="gray">
        <color rgba="0.5 0.5 0.5 1.0"/>
      </material>
      <origin rpy="0 0 0" xyz="0 0 0.0"/>
    </visual>
    <collision>
      <geometry>
        <cylinder length="0.0" radius="0.02"/>
      </geometry>
    </collision>
  </link>
  <link name="third_link">
    <visual>
      <geometry>
        <cylinder length="0.3" radius="0.02"/>
      </geometry>
      <material name="gray">
        <color rgba="0.5 0.5 0.5 1.0"/>
      </material>
      <origin rpy="0 0 0" xyz="0 0 0.15"/>
    </visual>
    <collision>
      <geometry>
        <cylinder length="0.3" radius="0.02"/>
      </geometry>
    </collision>
  </link>
  <link name="elbow_link">
    <visual>
      <geometry>
        <box size="0.1 0.2 0.1"/>
      </geometry>
      <material name="gray">
        <color rgba="0.5 0.5 0.5 1.0"/>
      </material>
    </visual>
    <collision>
      <geometry>
        <box size="0.1 0.2 0.1"/>
      </geometry>
    </collision>
  </link>
  <link name="fourth_link">
    <visual>
      <geometry>
        <cylinder length="0.3" radius="0.02"/>
      </geometry>
      <material name="gray">
        <color rgba="0.5 0.5 0.5 1.0"/>
      </material>
      <origin rpy="0 0 0" xyz="0 0 0.15"/>
    </visual>
    <collision>
      <geometry>
        <cylinder length="0.3" radius="0.02"/>
      </geometry>
    </collision>
  </link>
  <link name="wrist_link">
    <visual>
      <geometry>
        <box size="0.1 0.1 0.1"/>
      </geometry>
      <material name="gray">
        <color rgba="0.5 0.5 0.5 1.0"/>
      </material>
    </visual>
    <collision>
      <geometry>
        <box size="0.1 0.1 0.1"/>
      </geometry>
    </collision>
  </link>
  <link name="differential">
    <visual>
      <geometry>
        <cylinder length="0.0" radius="0.02"/>
      </geometry>
      <material name="gray">
        <color rgba="0.5 0.5 0.5 1.0"/>
      </material>
      <origin rpy="0 0 0" xyz="0 0 0.0"/>
    </visual>
    <collision>
      <geometry>
        <cylinder length="0.0" radius="0.02"/>
      </geometry>
    </collision>
  </link>
  <link name="fifth_link">
    <visual>
      <geometry>
        <cylinder length="0.05" radius="0.01"/>
      </geometry>
      <material name="gray">
        <color rgba="0.5 0.5 0.5 1.0"/>
      </material>
      <origin rpy="0 0 0" xyz="0 0 0.025"/>
    </visual>
    <collision>
      <geometry>
        <cylinder length="0.05" radius="0.01"/>
      </geometry>
    </collision>
  </link>
  <joint name="base_joint" type="fixed">
    <origin rpy="0 0 0" xyz="0 0 0.07"/>
    <parent link="base_link"/>
    <child link="base_box"/>
  </joint>
  <joint name="joint1" type="revolute">
    <origin rpy="0 0 0" xyz="0 0 0.145"/>
    <axis xyz="0 0 1"/>
    <parent link="base_box"/>
    <child link="first_link"/>
    <limit effort="0.0" lower="-1.57" upper="1.57" velocity="0.95"/>
  </joint>
  <joint name="joint2" type="revolute">
    <origin rpy="0 0 0" xyz="0 0 0.075"/>
    <axis xyz="0 1 0"/>
    <parent link="first_link"/>
    <child link="second_link"/>
    <limit effort="0.0" lower="-1.57" upper="1.57" velocity="0.95"/>
  </joint>
  <joint name="joint3" type="revolute">
    <origin rpy="0 0 0" xyz="0 0 0"/>
    <axis xyz="0 0 1"/>
    <parent link="second_link"/>
    <child link="third_link"/>
    <limit effort="0.0" lower="-1.57" upper="1.57" velocity="0.95"/>
  </joint>
  <joint name="elbow_joint" type="fixed">
    <origin rpy="0 0 0" xyz="0 0.05 0.35"/>
    <parent link="third_link"/>
    <child link="elbow_link"/>
  </joint>
  <joint name="joint4" type="revolute">
    <origin rpy="0 0 0" xyz="0 0.05 0.05"/>
    <axis xyz="1 0 0"/>
    <parent link="elbow_link"/>
    <child link="fourth_link"/>
    <limit effort="0.0" lower="-1.57" upper="1.57" velocity="0.95"/>
  </joint>
  <joint name="joint5" type="revolute">
    <origin rpy="0 0 0" xyz="0 0 .3"/>
    <axis xyz="0 0 1"/>
    <parent link="fourth_link"/>
    <child link="wrist_link"/>
    <limit effort="0.0" lower="-1.57" upper="1.57" velocity="0.95"/>
  </joint>
  <joint name="joint6" type="revolute">
    <origin rpy="0 0 0" xyz="0 0 0.05"/>
    <axis xyz="0 1 0"/>
    <parent link="wrist_link"/>
    <child link="differential"/>
    <limit effort="0.0" lower="-1.57" upper="1.57" velocity="0.95"/>
  </joint>
  <joint name="joint7" type="revolute">
    <origin rpy="0 0 0" xyz="0 0 0"/>
    <axis xyz="0 0 1"/>
    <parent link="differential"/>
    <child link="fifth_link"/>
    <limit effort="0.0" lower="-1.57" upper="1.57" velocity="0.95"/>
  </joint>
</robot>

