<?xml version="1.0" ?>
<!-- =================================================================================== -->
<!-- |    This document was autogenerated by xacro from cuarm.xacro                    | -->
<!-- |    EDITING THIS FILE BY HAND IS NOT RECOMMENDED                                 | -->
<!-- =================================================================================== -->
<robot name="cuarm" xmlns:xacro="http://www.ros.org/wiki/xacro">
  <!-- math constants -->
  <!-- staubli geometry files are in millimeters -->
  <!-- named paths -->
  <!-- link macro -->
  <!-- Colors -->
  <!-- useful macros -->
  <link name="base_link">
    <visual>
      <geometry>
        <cylinder length="0.0" radius="0.02"/>
      </geometry>
      <material name="gray">
        <color rgba="0.5 0.5 0.5 1.0"/>
      </material>
      <origin rpy="0 0 0" xyz="0 0 0.0"/>
    </visual>
    <collision>
      <geometry>
        <cylinder length="0.0" radius="0.02"/>
      </geometry>
      <origin rpy="0 0 0" xyz="0 0 0.0"/>
    </collision>
  </link>
  <joint name="base_joint" type="fixed">
    <origin rpy="0 0 0" xyz="0 0 0"/>
    <parent link="base_link"/>
    <child link="base_box"/>
  </joint>
  <link name="base_box">
    <visual>
      <geometry>
        <box size="0.14 0.2 0.085"/>
      </geometry>
      <material name="yellow">
        <color rgba="0.75 0.75 0 1.0"/>
      </material>
      <origin rpy="0 0 0" xyz="0 0 0.0425"/>
    </visual>
    <collision>
      <geometry>
        <box size="0.14 0.2 0.085"/>
      </geometry>
      <origin rpy="0 0 0" xyz="0 0 0.0425"/>
    </collision>
  </link>
  <joint name="base_rotate" type="revolute">
    <origin rpy="0 0 0" xyz="0.025 0 0.085"/>
    <axis xyz="0 0 1"/>
    <parent link="base_box"/>
    <child link="carbon_fiber_link"/>
    <limit effort="1.0" lower="-1.57" upper="1.57" velocity="0.3"/>
  </joint>
  <link name="carbon_fiber_link">
    <visual>
      <geometry>
        <cylinder length="0.14" radius="0.02"/>
      </geometry>
      <material name="dark_gray">
        <color rgba="0.3 0.3 0.3 1.0"/>
      </material>
      <origin rpy="0 0 0" xyz="0 0 0.07"/>
    </visual>
    <collision>
      <geometry>
        <cylinder length="0.14" radius="0.02"/>
      </geometry>
      <origin rpy="0 0 0" xyz="0 0 0.07"/>
    </collision>
  </link>
  <joint name="fixed_link_to_elbow" type="fixed">
    <origin rpy="0 0 0" xyz="0 0 0.14"/>
    <parent link="carbon_fiber_link"/>
    <child link="elbow_link_vertical"/>
  </joint>
  <link name="elbow_link_vertical">
    <visual>
      <geometry>
        <box size="0.1 0.1 0.2"/>
      </geometry>
      <material name="yellow">
        <color rgba="0.75 0.75 0 1.0"/>
      </material>
      <origin rpy="0 0 0" xyz="0 0 0.1"/>
    </visual>
    <collision>
      <geometry>
        <box size="0.1 0.1 0.2"/>
      </geometry>
      <origin rpy="0 0 0" xyz="0 0 0.1"/>
    </collision>
  </link>
  <joint name="fixed_elbow_internal" type="fixed">
    <origin rpy="0 0 0" xyz="0 0.05 0.10"/>
    <parent link="elbow_link_vertical"/>
    <child link="elbow_link_horizontal"/>
  </joint>
  <link name="elbow_link_horizontal">
    <visual>
      <geometry>
        <box size="0.1 0.2 0.1"/>
      </geometry>
      <material name="blue">
        <color rgba="0 0 0.75 1.0"/>
      </material>
      <origin rpy="0 0 0" xyz="0 0 0.05"/>
    </visual>
    <collision>
      <geometry>
        <box size="0.1 0.2 0.1"/>
      </geometry>
      <origin rpy="0 0 0" xyz="0 0 0.05"/>
    </collision>
  </link>
  <joint name="elbow_lift" type="revolute">
    <origin rpy="0 0 0" xyz="0 0.05 0.10"/>
    <axis xyz="1 0 0"/>
    <parent link="elbow_link_horizontal"/>
    <child link="carbon_fiber_link_2"/>
    <limit effort="1.0" lower="-2.09" upper="0.52" velocity="0.3"/>
  </joint>
  <link name="carbon_fiber_link_2">
    <visual>
      <geometry>
        <cylinder length="0.1" radius="0.02"/>
      </geometry>
      <material name="dark_gray">
        <color rgba="0.3 0.3 0.3 1.0"/>
      </material>
      <origin rpy="0 0 0" xyz="0 0 0.05"/>
    </visual>
    <collision>
      <geometry>
        <cylinder length="0.1" radius="0.02"/>
      </geometry>
      <origin rpy="0 0 0" xyz="0 0 0.05"/>
    </collision>
  </link>
  <joint name="fixed_link_to_wrist" type="fixed">
    <origin rpy="0 0 0" xyz="0 0 0.10"/>
    <parent link="carbon_fiber_link_2"/>
    <child link="wrist_base_link"/>
  </joint>
  <link name="wrist_base_link">
    <visual>
      <geometry>
        <box size="0.1 0.1 0.1"/>
      </geometry>
      <material name="yellow">
        <color rgba="0.75 0.75 0 1.0"/>
      </material>
      <origin rpy="0 0 0" xyz="0 0 0.05"/>
    </visual>
    <collision>
      <geometry>
        <box size="0.1 0.1 0.1"/>
      </geometry>
      <origin rpy="0 0 0" xyz="0 0 0.05"/>
    </collision>
  </link>
  <joint name="wrist_rotate" type="revolute">
    <origin rpy="0 0 0" xyz="0 0 0.10"/>
    <axis xyz="0 0 1"/>
    <parent link="wrist_base_link"/>
    <child link="differential_link"/>
    <limit effort="1.0" lower="-1.57" upper="1.57" velocity="0.3"/>
  </joint>
  <link name="differential_link">
    <visual>
      <geometry>
        <box size="0.1 0.1 0.15"/>
      </geometry>
      <material name="olive">
        <color rgba="0.5 0.5 0 1.0"/>
      </material>
      <origin rpy="0 0 0" xyz="0 0 0.075"/>
    </visual>
    <collision>
      <geometry>
        <box size="0.1 0.1 0.15"/>
      </geometry>
      <origin rpy="0 0 0" xyz="0 0 0.075"/>
    </collision>
  </link>
  <joint name="differential_rotate" type="revolute">
    <origin rpy="0 0 0" xyz="0 0 0.105"/>
    <axis xyz="0 0 1"/>
    <parent link="differential_link"/>
    <child link="diff_crossbar"/>
    <limit effort="1.0" lower="-1.57" upper="1.57" velocity="0.3"/>
  </joint>
  <link name="diff_crossbar">
    <visual>
      <geometry>
        <box size="0.0 0.0 0.0"/>
      </geometry>
      <material name="olive">
        <color rgba="0.5 0.5 0 1.0"/>
      </material>
      <origin rpy="0 0 0" xyz="0 0 0.0"/>
    </visual>
    <collision>
      <geometry>
        <box size="0.0 0.0 0.0"/>
      </geometry>
      <origin rpy="0 0 0" xyz="0 0 0.0"/>
    </collision>
  </link>
  <joint name="differential_lift" type="revolute">
    <origin rpy="0 0 0" xyz="0 0 0"/>
    <axis xyz="1 0 0"/>
    <parent link="diff_crossbar"/>
    <child link="gripper_connect_link"/>
    <limit effort="1.0" lower="-1.57" upper="1.57" velocity="0.3"/>
  </joint>
  <link name="gripper_connect_link">
    <visual>
      <geometry>
        <cylinder length="0.045" radius="0.005"/>
      </geometry>
      <material name="gray">
        <color rgba="0.5 0.5 0.5 1.0"/>
      </material>
      <origin rpy="0 0 0" xyz="0 0 0.0225"/>
    </visual>
    <collision>
      <geometry>
        <cylinder length="0.045" radius="0.005"/>
      </geometry>
      <origin rpy="0 0 0" xyz="0 0 0.0225"/>
    </collision>
  </link>
  <joint name="fixed_link_to_gripper" type="fixed">
    <origin rpy="0 0 0" xyz="0 0 0.045"/>
    <parent link="gripper_connect_link"/>
    <child link="gripper_frame"/>
  </joint>
  <link name="gripper_frame">
    <visual>
      <geometry>
        <box size="0.085 0.075 0.15"/>
      </geometry>
      <material name="yellow">
        <color rgba="0.75 0.75 0 1.0"/>
      </material>
      <origin rpy="0 0 0" xyz="0 0 0.075"/>
    </visual>
    <collision>
      <geometry>
        <box size="0.085 0.075 0.15"/>
      </geometry>
      <origin rpy="0 0 0" xyz="0 0 0.075"/>
    </collision>
  </link>
  <joint name="fixed_link_to_hand" type="fixed">
    <origin rpy="0 0 0" xyz="0 0 0.15"/>
    <parent link="gripper_frame"/>
    <child link="gripper_hand"/>
  </joint>
  <link name="gripper_hand">
    <visual>
      <geometry>
        <cylinder length="0.17" radius="0.04"/>
      </geometry>
      <material name="blue">
        <color rgba="0 0 0.75 1.0"/>
      </material>
      <origin rpy="0 0 0" xyz="0 0 0.085"/>
    </visual>
    <collision>
      <geometry>
        <cylinder length="0.17" radius="0.04"/>
      </geometry>
      <origin rpy="0 0 0" xyz="0 0 0.085"/>
    </collision>
  </link>
</robot>

